Workbook

Sheet DesignValues
A1: AQS ID | B1: Local Site Name | C1: ANNUAL_DESIGN_VALUE | D1: DAILY_DESIGN_VALUE
A2: 06-001-0007 | B2: =VLOOKUP(A2, IDDataBase!A:B, 2, FALSE) -> Livermore | C2: 5.6 | D2: 19
A3: 06-001-0009 | B3: =VLOOKUP(A3, IDDataBase!A:B, 2, FALSE) -> Oakland | C3: 6.3 | D3: 16
A4: 06-001-0011 | B4: =VLOOKUP(A4, IDDataBase!A:B, 2, FALSE) -> Oakland West | C4: 6.5 | D4: 20
A5: 06-001-0012 | B5: =VLOOKUP(A5, IDDataBase!A:B, 2, FALSE) -> Laney College | C5: 8.3 | D5: 21
A6: 06-001-0013 | B6: =VLOOKUP(A6, IDDataBase!A:B, 2, FALSE) -> Berkeley- Aquatic Park | C6: 7.8 | D6: 19
A7: 06-001-0015 | B7: =VLOOKUP(A7, IDDataBase!A:B, 2, FALSE) -> Pleasanton - Owens Ct | C7: 6.3 | D7: 19
A8: 06-001-0016 | B8: =VLOOKUP(A8, IDDataBase!A:B, 2, FALSE) -> Livermore Portola | C8: 6.3 | D8: 17
A9: 06-007-0008 | B9: =VLOOKUP(A9, IDDataBase!A:B, 2, FALSE) -> Chico-East Avenue | C9: 7.3 | D9: 24
A10: 06-009-0001 | B10: =VLOOKUP(A10, IDDataBase!A:B, 2, FALSE) -> San Andreas-Gold Strike Road | C10: 5.4 | D10: 13
A11: 06-011-1002 | B11: =VLOOKUP(A11, IDDataBase!A:B, 2, FALSE) -> Colusa-Sunrise Blvd | C11: 6.5 | D11: 19
A12: 06-013-0002 | B12: =VLOOKUP(A12, IDDataBase!A:B, 2, FALSE) -> Concord | C12: 5.1 | D12: 17
A13: 06-013-1004 | B13: =VLOOKUP(A13, IDDataBase!A:B, 2, FALSE) -> San Pablo | C13: 9.8 | D13: 22
... A117: 06-111-3001 | B117: =VLOOKUP(A117, IDDataBase!A:B, 2, FALSE) -> El Rio-Rio Mesa School #2 | C117: 6.1 | D117: 13
B118: =VLOOKUP(A118, IDDataBase!A:B, 2, FALSE) -> #N/A | C118: 8.1 | D118: 23

Sheet AgencyName
A1: AQS ID | B1: Agency_Name
A2: 06-001-0005 | B2: Bay Area Air Quality Management District
A3: 06-001-0006 | B3: Bay Area Air Quality Management District
A4: 06-001-0007 | B4: Bay Area Air Quality Management District
A5: 06-001-0008 | B5: Bay Area Air Quality Management District
A6: 06-001-0009 | B6: Bay Area Air Quality Management District
A7: 06-001-0011 | B7: Bay Area Air Quality Management District
A8: 06-001-0012 | B8: Bay Area Air Quality Management District
A9: 06-001-0013 | B9: Bay Area Air Quality Management District
A10: 06-001-0015 | B10: Bay Area Air Quality Management District
A11: 06-001-0016 | B11: Bay Area Air Quality Management District
A12: 06-001-1001 | B12: Bay Area Air Quality Management District
... A499: 06-113-2001 | B499: Yolo-Solano APCD

Sheet IDDataBase
A1: AQS ID | B1: Local Site Name | C1: Extraction Date
A2: 06-001-0001 | B2: Berkeley | C2: 45986
A3: 06-001-0002 | B3: Fremont-Union St. | C3: 45986
A4: 06-001-0003 | B4: Livermore - Old 1st St. | C4: 45986
A5: 06-001-0004 | B5: Oakland-Jackson St. | C5: 45986
A6: 06-001-0005 | B6: Oakland - Alice | C6: 45986
A7: 06-001-0006 | B7: San Leandro | C7: 45986
A8: 06-001-0007 | B8: Livermore | C8: 45986
A9: 06-001-0008 | B9: Oakland - Filbert St. | C9: 45986
A10: 06-001-0009 | B10: Oakland | C10: 45986
A11: 06-001-0010 | B11: Oakland-International Blvd. | C11: 45986
A12: 06-001-0011 | B12: Oakland West | C12: 45986
A13: 06-001-0012 | B13: Laney College | C13: 45986
... A20: 06-001-2001 | B20: Hayward | C20: 45986
A21: 06-001-2002 | C21: 45986
A22: 06-001-2003 | B22: Piedmont | C22: 45986
A23: 06-001-2004 | B23: Berkeley | C23: 45986
A24: 06-001-2005 | B24: Patterson Pass | C24: 45986
A25: 06-001-3001 | C25: 45986
A26: 06-001-4001 | B26: Oakland-City HQ | C26: 45986
A27: 06-001-5001 | B27: San Leandro-Thornton Ave. | C27: 45986
A28: 06-001-5002 | B28: ROOF OF THE UC BERKELEY SPACE SCIENCE BUILDING | C28: 45986
A29: 06-001-6001 | B29: Chabot | C29: 45986
A30: 06-001-6002 | B30: Sunol | C30: 45986
A31: 06-001-6003 | B31: Pleasanton | C31: 45986
A32: 06-001-6004 | B32: Patterson Pass | C32: 45986
A33: 06-003-1001 | C33: 45986
A34: 06-005-0002 | B34: Jackson-Clinton Road | C34: 45986
A35: 06-005-0010 | B35: Jackson-Buena Vista Rd. | C35: 45986
A36: 06-005-0011 | B36: Jackson-5730 Buena Vista Rd. | C36: 45986
A37: 06-005-1033 | B37: Kirkwood | C37: 45986
A38: 06-007-0001 | B38: Chico-Oleander Ave. | C38: 45986
A39: 06-007-0002 | B39: Chico-Manzanita Ave. | C39: 45986
A40: 06-007-0003 | B40: Chico-Holt Hall, CSU Chico | C40: 45986
A41: 06-007-0004 | B41: GRIDLEY - 608 COWEE AVENUE | C41: 45986
A42: 06-007-0005 | B42: Chico-Salem St. | C42: 45986
A43: 06-007-0006 | B43: PARADISE ROVER STUDY | C43: 45986
A44: 06-007-0007 | B44: Paradise - Airport | C44: 45986
A45: 06-007-0008 | B45: Chico-East Avenue | C45: 45986
A46: 06-007-1001 | C46: 45986
...

Sheet AgencyPQAO
A1: Agency | B1: PQAO
A2: Bay Area Air Quality Management District | B2: BAAQMD
A3: California Air Resources Board | B3: CARB
A4: Great Basin Unified APCD | B4: CARB
A5: Imperial County APCD | B5: CARB
A6: Kern County APCD | B6: CARB
A7: Lake County AQMD | B7: CARB
A8: Mendocino County APCD | B8: CARB
A9: Mojave Desert AQMD | B9: CARB
A10: Monterey Bay Unified APCD | B10: CARB
A11: National Park Service | B11: NPS
A12: Northern Sierra AQMD | B12: CARB
... A24: Yolo-Solano APCD | B24: CARB
